Exception in connection handler
Traceback (most recent call last):
  File "/usr/local/lib/python3.5/dist-packages/websockets/server.py", line 78, in handler
    yield from self.ws_handler(self, path)
  File "server/main.py", line 522, in handler
    dec_sendmsg = consumer(dec_recvmsg)
  File "server/main.py", line 25, in consumer
    if (recvmessage["keyword"] in switchcases): return switchcases[recvmessage["keyword"]](recvmessage["data"], recvmessage["user"])
  File "server/main.py", line 379, in validate_fm
    return provide_learning(data, name)
  File "server/main.py", line 202, in provide_learning
    if (user["flashmap_condition"]): msg = provide_flashedges(data, name)
  File "server/main.py", line 267, in provide_flashedges
    return new_flashedge(name)
  File "server/main.py", line 282, in new_flashedge
    edge = db.cmap.find_one()["edges"][i]
IndexError: list index out of range
Exception in connection handler
Traceback (most recent call last):
  File "/usr/local/lib/python3.5/dist-packages/websockets/server.py", line 78, in handler
    yield from self.ws_handler(self, path)
  File "server/main.py", line 522, in handler
    dec_sendmsg = consumer(dec_recvmsg)
  File "server/main.py", line 25, in consumer
    if (recvmessage["keyword"] in switchcases): return switchcases[recvmessage["keyword"]](recvmessage["data"], recvmessage["user"])
  File "server/main.py", line 379, in validate_fm
    return provide_learning(data, name)
  File "server/main.py", line 202, in provide_learning
    if (user["flashmap_condition"]): msg = provide_flashedges(data, name)
  File "server/main.py", line 267, in provide_flashedges
    return new_flashedge(name)
  File "server/main.py", line 282, in new_flashedge
    edge = db.cmap.find_one()["edges"][i]
IndexError: list index out of range
Exception in connection handler
Traceback (most recent call last):
  File "/usr/local/lib/python3.5/dist-packages/websockets/server.py", line 78, in handler
    yield from self.ws_handler(self, path)
  File "server/main.py", line 522, in handler
    dec_sendmsg = consumer(dec_recvmsg)
  File "server/main.py", line 25, in consumer
    if (recvmessage["keyword"] in switchcases): return switchcases[recvmessage["keyword"]](recvmessage["data"], recvmessage["user"])
  File "server/main.py", line 379, in validate_fm
    return provide_learning(data, name)
  File "server/main.py", line 202, in provide_learning
    if (user["flashmap_condition"]): msg = provide_flashedges(data, name)
  File "server/main.py", line 267, in provide_flashedges
    return new_flashedge(name)
  File "server/main.py", line 282, in new_flashedge
    edge = db.cmap.find_one()["edges"][i]
IndexError: list index out of range
Exception in connection handler
Traceback (most recent call last):
  File "/usr/local/lib/python3.5/dist-packages/websockets/server.py", line 78, in handler
    yield from self.ws_handler(self, path)
  File "server/main.py", line 522, in handler
    dec_sendmsg = consumer(dec_recvmsg)
  File "server/main.py", line 25, in consumer
    if (recvmessage["keyword"] in switchcases): return switchcases[recvmessage["keyword"]](recvmessage["data"], recvmessage["user"])
  File "server/main.py", line 202, in provide_learning
    if (user["flashmap_condition"]): msg = provide_flashedges(data, name)
  File "server/main.py", line 267, in provide_flashedges
    return new_flashedge(name)
  File "server/main.py", line 282, in new_flashedge
    edge = db.cmap.find_one()["edges"][i]
IndexError: list index out of range
Exception in connection handler
Traceback (most recent call last):
  File "/usr/local/lib/python3.5/dist-packages/websockets/server.py", line 78, in handler
    yield from self.ws_handler(self, path)
  File "server/main.py", line 522, in handler
    dec_sendmsg = consumer(dec_recvmsg)
  File "server/main.py", line 25, in consumer
    if (recvmessage["keyword"] in switchcases): return switchcases[recvmessage["keyword"]](recvmessage["data"], recvmessage["user"])
  File "server/main.py", line 379, in validate_fm
    return provide_learning(data, name)
  File "server/main.py", line 202, in provide_learning
    if (user["flashmap_condition"]): msg = provide_flashedges(data, name)
  File "server/main.py", line 267, in provide_flashedges
    return new_flashedge(name)
  File "server/main.py", line 282, in new_flashedge
    edge = db.cmap.find_one()["edges"][i]
IndexError: list index out of range
Exception in connection handler
Traceback (most recent call last):
  File "/usr/local/lib/python3.5/dist-packages/websockets/server.py", line 78, in handler
    yield from self.ws_handler(self, path)
  File "server/main.py", line 522, in handler
    dec_sendmsg = consumer(dec_recvmsg)
  File "server/main.py", line 25, in consumer
    if (recvmessage["keyword"] in switchcases): return switchcases[recvmessage["keyword"]](recvmessage["data"], recvmessage["user"])
  File "server/main.py", line 379, in validate_fm
    return provide_learning(data, name)
  File "server/main.py", line 202, in provide_learning
    if (user["flashmap_condition"]): msg = provide_flashedges(data, name)
  File "server/main.py", line 267, in provide_flashedges
    return new_flashedge(name)
  File "server/main.py", line 282, in new_flashedge
    edge = db.cmap.find_one()["edges"][i]
IndexError: list index out of range
Exception in connection handler
Traceback (most recent call last):
  File "/usr/local/lib/python3.5/dist-packages/websockets/server.py", line 78, in handler
    yield from self.ws_handler(self, path)
  File "server/main.py", line 522, in handler
    dec_sendmsg = consumer(dec_recvmsg)
  File "server/main.py", line 25, in consumer
    if (recvmessage["keyword"] in switchcases): return switchcases[recvmessage["keyword"]](recvmessage["data"], recvmessage["user"])
  File "server/main.py", line 379, in validate_fm
    return provide_learning(data, name)
  File "server/main.py", line 202, in provide_learning
    if (user["flashmap_condition"]): msg = provide_flashedges(data, name)
  File "server/main.py", line 267, in provide_flashedges
    return new_flashedge(name)
  File "server/main.py", line 282, in new_flashedge
    edge = db.cmap.find_one()["edges"][i]
IndexError: list index out of range
Exception in connection handler
Traceback (most recent call last):
  File "/usr/local/lib/python3.5/dist-packages/websockets/server.py", line 78, in handler
    yield from self.ws_handler(self, path)
  File "server/main.py", line 522, in handler
    dec_sendmsg = consumer(dec_recvmsg)
  File "server/main.py", line 25, in consumer
    if (recvmessage["keyword"] in switchcases): return switchcases[recvmessage["keyword"]](recvmessage["data"], recvmessage["user"])
  File "server/main.py", line 379, in validate_fm
    return provide_learning(data, name)
  File "server/main.py", line 202, in provide_learning
    if (user["flashmap_condition"]): msg = provide_flashedges(data, name)
  File "server/main.py", line 267, in provide_flashedges
    return new_flashedge(name)
  File "server/main.py", line 282, in new_flashedge
    edge = db.cmap.find_one()["edges"][i]
IndexError: list index out of range
Exception in connection handler
Traceback (most recent call last):
  File "/usr/local/lib/python3.5/dist-packages/websockets/server.py", line 78, in handler
    yield from self.ws_handler(self, path)
  File "server/main.py", line 522, in handler
    dec_sendmsg = consumer(dec_recvmsg)
  File "server/main.py", line 25, in consumer
    if (recvmessage["keyword"] in switchcases): return switchcases[recvmessage["keyword"]](recvmessage["data"], recvmessage["user"])
  File "server/main.py", line 202, in provide_learning
    if (user["flashmap_condition"]): msg = provide_flashedges(data, name)
  File "server/main.py", line 267, in provide_flashedges
    return new_flashedge(name)
  File "server/main.py", line 282, in new_flashedge
    edge = db.cmap.find_one()["edges"][i]
IndexError: list index out of range
Exception in connection handler
Traceback (most recent call last):
  File "/usr/local/lib/python3.5/dist-packages/websockets/server.py", line 78, in handler
    yield from self.ws_handler(self, path)
  File "server/main.py", line 522, in handler
    dec_sendmsg = consumer(dec_recvmsg)
  File "server/main.py", line 25, in consumer
    if (recvmessage["keyword"] in switchcases): return switchcases[recvmessage["keyword"]](recvmessage["data"], recvmessage["user"])
  File "server/main.py", line 202, in provide_learning
    if (user["flashmap_condition"]): msg = provide_flashedges(data, name)
  File "server/main.py", line 267, in provide_flashedges
    return new_flashedge(name)
  File "server/main.py", line 282, in new_flashedge
    edge = db.cmap.find_one()["edges"][i]
IndexError: list index out of range
Exception in connection handler
Traceback (most recent call last):
  File "/usr/local/lib/python3.5/dist-packages/websockets/server.py", line 78, in handler
    yield from self.ws_handler(self, path)
  File "server/main.py", line 522, in handler
    dec_sendmsg = consumer(dec_recvmsg)
  File "server/main.py", line 25, in consumer
    if (recvmessage["keyword"] in switchcases): return switchcases[recvmessage["keyword"]](recvmessage["data"], recvmessage["user"])
  File "server/main.py", line 198, in provide_learning
    return {"keyword" : "READ_SOURCE-REQUEST", "data": {"source" : SOURCES[len(user["read_sources"])]}}
IndexError: list index out of range
Exception in connection handler
Traceback (most recent call last):
  File "/usr/local/lib/python3.5/dist-packages/websockets/server.py", line 78, in handler
    yield from self.ws_handler(self, path)
  File "server/main.py", line 522, in handler
    dec_sendmsg = consumer(dec_recvmsg)
  File "server/main.py", line 25, in consumer
    if (recvmessage["keyword"] in switchcases): return switchcases[recvmessage["keyword"]](recvmessage["data"], recvmessage["user"])
  File "server/main.py", line 198, in provide_learning
    return {"keyword" : "READ_SOURCE-REQUEST", "data": {"source" : SOURCES[len(user["read_sources"])]}}
IndexError: list index out of range
Exception in connection handler
Traceback (most recent call last):
  File "/usr/local/lib/python3.5/dist-packages/websockets/server.py", line 78, in handler
    yield from self.ws_handler(self, path)
  File "server/main.py", line 522, in handler
    dec_sendmsg = consumer(dec_recvmsg)
  File "server/main.py", line 25, in consumer
    if (recvmessage["keyword"] in switchcases): return switchcases[recvmessage["keyword"]](recvmessage["data"], recvmessage["user"])
  File "server/main.py", line 198, in provide_learning
    return {"keyword" : "READ_SOURCE-REQUEST", "data": {"source" : SOURCES[len(user["read_sources"])]}}
IndexError: list index out of range
Exception in connection handler
Traceback (most recent call last):
  File "/usr/local/lib/python3.5/dist-packages/websockets/server.py", line 78, in handler
    yield from self.ws_handler(self, path)
  File "server/main.py", line 522, in handler
    dec_sendmsg = consumer(dec_recvmsg)
  File "server/main.py", line 25, in consumer
    if (recvmessage["keyword"] in switchcases): return switchcases[recvmessage["keyword"]](recvmessage["data"], recvmessage["user"])
  File "server/main.py", line 198, in provide_learning
    return {"keyword" : "READ_SOURCE-REQUEST", "data": {"source" : SOURCES[len(user["read_sources"])]}}
IndexError: list index out of range
Exception in connection handler
Traceback (most recent call last):
  File "/usr/local/lib/python3.5/dist-packages/websockets/server.py", line 78, in handler
    yield from self.ws_handler(self, path)
  File "server/main.py", line 522, in handler
    dec_sendmsg = consumer(dec_recvmsg)
  File "server/main.py", line 25, in consumer
    if (recvmessage["keyword"] in switchcases): return switchcases[recvmessage["keyword"]](recvmessage["data"], recvmessage["user"])
  File "server/main.py", line 198, in provide_learning
    return {"keyword" : "READ_SOURCE-REQUEST", "data": {"source" : SOURCES[len(user["read_sources"])]}}
IndexError: list index out of range
Exception in connection handler
Traceback (most recent call last):
  File "/usr/local/lib/python3.5/dist-packages/websockets/server.py", line 78, in handler
    yield from self.ws_handler(self, path)
  File "server/audit.py", line 123, in handler
    dec_sendmsg = consumer(dec_recvmsg)
  File "server/audit.py", line 23, in consumer
    if (recvmessage["keyword"] in switchcases): return switchcases[recvmessage["keyword"]](recvmessage["data"], recvmessage["user"])
  File "server/audit.py", line 82, in add_item
    return provide_item(data, name)
  File "server/audit.py", line 57, in provide_item
    if (db.irrfcards.count() == db.audits.aggregate([{"$project": {"name": "mieke_vennink", "count": {"$size": "$flashcards"}}}])["count"]
  File "/usr/local/lib/python3.5/dist-packages/pymongo/collection.py", line 1671, in aggregate
    read_concern=self.read_concern)
  File "/usr/local/lib/python3.5/dist-packages/pymongo/collection.py", line 205, in _command
    read_concern=read_concern)
  File "/usr/local/lib/python3.5/dist-packages/pymongo/pool.py", line 213, in command
    read_concern)
  File "/usr/local/lib/python3.5/dist-packages/pymongo/network.py", line 99, in command
    helpers._check_command_response(response_doc, None, allowable_errors)
  File "/usr/local/lib/python3.5/dist-packages/pymongo/helpers.py", line 196, in _check_command_response
    raise OperationFailure(msg % errmsg, code, response)
pymongo.errors.OperationFailure: FieldPath 'mieke_vennink' doesn't start with $
Exception in connection handler
Traceback (most recent call last):
  File "/usr/local/lib/python3.5/dist-packages/websockets/server.py", line 78, in handler
    yield from self.ws_handler(self, path)
  File "server/audit.py", line 123, in handler
    dec_sendmsg = consumer(dec_recvmsg)
  File "server/audit.py", line 23, in consumer
    if (recvmessage["keyword"] in switchcases): return switchcases[recvmessage["keyword"]](recvmessage["data"], recvmessage["user"])
  File "server/audit.py", line 57, in provide_item
    if (db.irrfcards.count() == db.audits.aggregate([{"$project": {"name": "mieke_vennink", "count": {"$size": "$flashcards"}}}])["count"]
  File "/usr/local/lib/python3.5/dist-packages/pymongo/collection.py", line 1671, in aggregate
    read_concern=self.read_concern)
  File "/usr/local/lib/python3.5/dist-packages/pymongo/collection.py", line 205, in _command
    read_concern=read_concern)
  File "/usr/local/lib/python3.5/dist-packages/pymongo/pool.py", line 213, in command
    read_concern)
  File "/usr/local/lib/python3.5/dist-packages/pymongo/network.py", line 99, in command
    helpers._check_command_response(response_doc, None, allowable_errors)
  File "/usr/local/lib/python3.5/dist-packages/pymongo/helpers.py", line 196, in _check_command_response
    raise OperationFailure(msg % errmsg, code, response)
pymongo.errors.OperationFailure: FieldPath 'mieke_vennink' doesn't start with $
Traceback (most recent call last):
  File "server/main.py", line 542, in <module>
    asyncio.get_event_loop().run_until_complete(start_server)
  File "/usr/lib/python3.5/asyncio/base_events.py", line 387, in run_until_complete
    return future.result()
  File "/usr/lib/python3.5/asyncio/futures.py", line 274, in result
    raise self._exception
  File "/usr/lib/python3.5/asyncio/tasks.py", line 241, in _step
    result = coro.throw(exc)
  File "/usr/local/lib/python3.5/dist-packages/websockets/server.py", line 306, in serve
    server = yield from loop.create_server(factory, host, port, **kwds)
  File "/usr/lib/python3.5/asyncio/base_events.py", line 923, in create_server
    infos = yield from tasks.gather(*fs, loop=self)
  File "/usr/lib/python3.5/asyncio/futures.py", line 361, in __iter__
    yield self  # This tells Task to wait for completion.
  File "/usr/lib/python3.5/asyncio/tasks.py", line 296, in _wakeup
    future.result()
  File "/usr/lib/python3.5/asyncio/futures.py", line 274, in result
    raise self._exception
  File "/usr/lib/python3.5/asyncio/tasks.py", line 241, in _step
    result = coro.throw(exc)
  File "/usr/lib/python3.5/asyncio/base_events.py", line 871, in _create_server_getaddrinfo
    flags=flags, loop=self)
  File "/usr/lib/python3.5/asyncio/futures.py", line 361, in __iter__
    yield self  # This tells Task to wait for completion.
  File "/usr/lib/python3.5/asyncio/tasks.py", line 296, in _wakeup
    future.result()
  File "/usr/lib/python3.5/asyncio/futures.py", line 274, in result
    raise self._exception
  File "/usr/lib/python3.5/concurrent/futures/thread.py", line 55, in run
    result = self.fn(*self.args, **self.kwargs)
  File "/usr/lib/python3.5/socket.py", line 732, in getaddrinfo
    for res in _socket.getaddrinfo(host, port, family, type, proto, flags):
socket.gaierror: [Errno -2] Name or service not known
Traceback (most recent call last):
  File "server/main.py", line 542, in <module>
    asyncio.get_event_loop().run_until_complete(start_server)
  File "/usr/lib/python3.5/asyncio/base_events.py", line 387, in run_until_complete
    return future.result()
  File "/usr/lib/python3.5/asyncio/futures.py", line 274, in result
    raise self._exception
  File "/usr/lib/python3.5/asyncio/tasks.py", line 241, in _step
    result = coro.throw(exc)
  File "/usr/local/lib/python3.5/dist-packages/websockets/server.py", line 306, in serve
    server = yield from loop.create_server(factory, host, port, **kwds)
  File "/usr/lib/python3.5/asyncio/base_events.py", line 923, in create_server
    infos = yield from tasks.gather(*fs, loop=self)
  File "/usr/lib/python3.5/asyncio/futures.py", line 361, in __iter__
    yield self  # This tells Task to wait for completion.
  File "/usr/lib/python3.5/asyncio/tasks.py", line 296, in _wakeup
    future.result()
  File "/usr/lib/python3.5/asyncio/futures.py", line 274, in result
    raise self._exception
  File "/usr/lib/python3.5/asyncio/tasks.py", line 241, in _step
    result = coro.throw(exc)
  File "/usr/lib/python3.5/asyncio/base_events.py", line 871, in _create_server_getaddrinfo
    flags=flags, loop=self)
  File "/usr/lib/python3.5/asyncio/futures.py", line 361, in __iter__
    yield self  # This tells Task to wait for completion.
  File "/usr/lib/python3.5/asyncio/tasks.py", line 296, in _wakeup
    future.result()
  File "/usr/lib/python3.5/asyncio/futures.py", line 274, in result
    raise self._exception
  File "/usr/lib/python3.5/concurrent/futures/thread.py", line 55, in run
    result = self.fn(*self.args, **self.kwargs)
  File "/usr/lib/python3.5/socket.py", line 732, in getaddrinfo
    for res in _socket.getaddrinfo(host, port, family, type, proto, flags):
socket.gaierror: [Errno -2] Name or service not known
